Workbook

Sheet Analysis Tables
A1: Metric | B1: Value
A2: Valid Responses Analysed | B2: =ROWS('Analysis Data'!AJ3:AJ39) -> 37 | E2: Loyalty Metric | F2: Value
E3: Mean Loyalty Index | F3: 3.8864865
E4: Standard Deviation | F4: 0.89136667
E5: Minimum Loyalty Index | F5: 1
A6: Loyalty Metric | B6: Value | E6: Maximum Loyalty Index | F6: 5
A7: Mean Loyalty Index | B7: =AVERAGE('Analysis Data'!AJ3:AJ39) -> 3.8864865
A8: Standard Deviation | B8: =_xlfn.STDEV.S('Analysis Data'!AJ3:AJ39) -> 0.89136667
A9: Minimum Loyalty Index | B9: =MIN('Analysis Data'!AJ3:AJ39) -> 1
A10: Maximum Loyalty Index | B10: =MAX('Analysis Data'!AJ3:AJ39) -> 5
A16: NPS Category | B16: Count | C16: Percent
A17: Promoter | B17: =COUNTIF('Analysis Data'!AK3:AK39,A17) -> 14 | C17: =B17/SUM($B$17:$B$19) -> 0.4
A18: Passive | B18: =COUNTIF('Analysis Data'!AK4:AK40,A18) -> 14 | C18: =B18/SUM($B$17:$B$19) -> 0.4
A19: Detractor | B19: =COUNTIF('Analysis Data'!AK5:AK41,A19) -> 7 | C19: =B19/SUM($B$17:$B$19) -> 0.2
A20: Total | B20: =SUM(B17:B19) -> 35 | C20: =SUM(C17:C19) -> 1
A22: Overall NPS | B22: =((B17/SUM($B$17:$B$19))-(B19/SUM($B$17:$B$19)))*100 -> 20
A25: Cancellation Risk | B25: Count | C25: Percent
A26: High Risk | B26: =COUNTIF('Analysis Data'!AL3:AL39,A26) -> 14 | C26: =B26/SUM($B$26:$B$27) -> 0.37837838
A27: Low/Moderate Risk | B27: =COUNTIF('Analysis Data'!AL4:AL40,A27) -> 23 | C27: =B27/SUM($B$26:$B$27) -> 0.62162162
A28: Total | B28: =SUM(B26:B27) -> 37 | C28: =SUM(C26:C27) -> 1 | F28: Cancellation Risk | G28: Count | H28: Percent
F29: High Risk | G29: 14 | H29: 0.37837838
F30: Low/Moderate Risk | G30: 23 | H30: 0.62162162
A31: Cancelled Past Year | B31: Count | C31: Percent | F31: Total | G31: 37 | H31: 1
A32: Yes | B32: =COUNTIF('Analysis Data'!AM3:AM39,A32) -> 6 | C32: =B32/$B$34 -> 0.16216216
A33: No | B33: =COUNTIF('Analysis Data'!AM3:AM40,A33) -> 31 | C33: =B33/$B$34 -> 0.83783784
A34: Total | B34: =SUM(B32:B33) -> 37 | C34: =SUM(C32:C33) -> 1
A37: Cancelled Past Year | B37: Mean Loyalty Index
A38: Yes | B38: =AVERAGEIF('Analysis Data'!AM3:AM39,A38,'Analysis Data'!AJ3:AJ39) -> 4.3333333
A39: No | B39: =AVERAGEIF('Analysis Data'!AM4:AM40,A39,'Analysis Data'!AJ4:AJ40) -> 3.7866667 | F39: Cancelled Past Year | G39: Count | H39: Percent
F40: Yes | G40: 6 | H40: 0.1622
F41: No | G41: 31 | H41: 0.8378
F42: Total | G42: 37 | H42: 1
A43: Chi-Square: Past Cancellation x Cancellation Risk
B44: High Risk | C44: Low/Moderate Risk | D44: Total
A45: Yes | B45: =COUNTIFS('Analysis Data'!AM3:AM39,"Yes",'Analysis Data'!AL3:AL39,"High risk") -> 0 | C45: =COUNTIFS('Analysis Data'!AM3:AM39,"Yes",'Analysis Data'!AL3:AL39,"Low/moderate risk") -> 6 | D45: =SUM(B45:C45) -> 6 | F45: Past Cancellation x Cancellation Risk
A46: No | B46: =COUNTIFS('Analysis Data'!AM3:AM39,"No",'Analysis Data'!AL3:AL39,"High risk") -> 14 | C46: =COUNTIFS('Analysis Data'!AM3:AM39,"No",'Analysis Data'!AL3:AL39,"Low/moderate risk") -> 17 | D46: =SUM(B46:C46) -> 31 | F46: Cancelled Past Year | G46: High Risk | H46: Low/Moderate Risk | I46: Total
A47: Total | B47: =SUM(B45:B46) -> 14 | C47: =SUM(C45:C46) -> 23 | D47: =SUM(D45:D46) -> 37 | F47: Yes | G47: 0 | H47: 6 | I47: 6
F48: No | G48: 14 | H48: 17 | I48: 31
F49: Total | G49: 14 | H49: 23 | I49: 37
B50: High Risk Expected | C50: Low/Moderate Risk Expected
...

Sheet Analysis Data
A1: StartDate | B1: EndDate | C1: Status | D1: IPAddress | E1: Progress | F1: Duration (in seconds) | G1: Finished | H1: RecordedDate | I1: ResponseId | J1: LocationLatitude | K1: LocationLongitude | L1: DistributionChannel | M1: UserLanguage | N1: Q1 | O1: Q2_1 | P1: Q2_2 | Q1: Q2_3 | R1: Q2_4 | S1: Q2_5 | T1: Q2_6 | U1: Q2_7 | V1: Q2_8 | W1: Q2_9 | X1: Q2_10 | Y1: Q3_1 | Z1: Q3_2 | AA1: Q3_3 | AB1: Q3_4 | AC1: Q3_5 | AD1: Q4_NPS_GROUP | AE1: Q4 | AF1: Q5 | AG1: Q6 | AH1: Q7 | AI1: Q8 | AJ1: Loyalty Index | AK1: NPS Category | AL1: Cancellation Risk | AM1: Cancelled A Service Within The Last Year
A2: Start Date | B2: End Date | C2: Response Type | D2: IP Address | E2: Progress | F2: Duration (in seconds) | G2: Finished | H2: Recorded Date | I2: Response ID | J2: Location Latitude | K2: Location Longitude | L2: Distribution Channel | M2: User Language | N2: Which statement best describes your role in streaming service decisions for your household? | O2: Please rank each streaming service based on how often you use it. Select First Most Used Service for the streaming service you use the most. Select Second Most Used Service for the service you use second most. Select Third Most Used Service for the service you use third most. For all other services, select Other (Not in top 3). - Netflix | P2: Please rank each streaming service based on how often you use it. Select First Most Used Service for the streaming service you use the most. Select Second Most Used Service for the service you use second most. Select Third Most Used Service for the service you use third most. For all other services, select Other (Not in top 3). - Hulu | Q2: Please rank each streaming service based on how often you use it. Select First Most Used Service for the streaming service you use the most. Select Second Most Used Service for the service you use second most. Select Third Most Used Service for the service you use third most. For all other services, select Other (Not in top 3). - Disney+ | R2: Please rank each streaming service based on how often you use it. Select First Most Used Service for the streaming service you use the most. Select Second Most Used Service for the service you use second most. Select Third Most Used Service for the service you use third most. For all other services, select Other (Not in top 3). - Max | S2: Please rank each streaming service based on how often you use it. Select First Most Used Service for the streaming service you use the most. Select Second Most Used Service for the service you use second most. Select Third Most Used Service for the service you use third most. For all other services, select Other (Not in top 3). - Prime Video | T2: Please rank each streaming service based on how often you use it. Select First Most Used Service for the streaming service you use the most. Select Second Most Used Service for the service you use second most. Select Third Most Used Service for the service you use third most. For all other services, select Other (Not in top 3). - Peacock | U2: Please rank each streaming service based on how often you use it. Select First Most Used Service for the streaming service you use the most. Select Second Most Used Service for the service you use second most. Select Third Most Used Service for the service you use third most. For all other services, select Other (Not in top 3). - Paramount+ | V2: Please rank each streaming service based on how often you use it. Select First Most Used Service for the streaming service you use the most. Select Second Most Used Service for the service you use second most. Select Third Most Used Service for the service you use third most. For all other services, select Other (Not in top 3). - Apple TV+ | W2: Please rank each streaming service based on how often you use it. Select First Most Used Service for the streaming service you use the most. Select Second Most Used Service for the service you use second most. Select Third Most Used Service for the service you use third most. For all other services, select Other (Not in top 3). - YouTube TV | X2: Please rank each streaming service based on how often you use it. Select First Most Used Service for the streaming service you use the most. Select Second Most Used Service for the service you use second most. Select Third Most Used Service for the service you use third most. For all other services, select Other (Not in top 3). - Other | Y2: Please indicate your level of agreement with the following statements about the streaming service you use most often. - I intend to keep using this streaming service. | Z2: Please indicate your level of agreement with the following statements about the streaming service you use most often. - This streaming service would be one of my first choices. | AA2: Please indicate your level of agreement with the following statements about the streaming service you use most often. - I would recommend this streaming service to others. | AB2: Please indicate your level of agreement with the following statements about the streaming service you use most often. - I would not easily switch to a competing streaming service. | AC2: Please indicate your level of agreement with the following statements about the streaming service you use most often. - I trust this streaming service. | AD2: How likely are you to recommend the streaming service you use most often to a friend or colleague? - Group | AE2: How likely are you to recommend the streaming service you use most often to a friend or colleague? | AF2: In the past 6 months, how often have you used the streaming service you ranked as #1? | AG2: How likely are you to cancel at least one streaming service in the next 6 months? | AH2: Have you canceled a streaming service within the past year? | AI2: What is the main reason you would continue using the streaming service you ranked as your first most used service? (Optional) | AJ2: Loyalty Index | AK2: NPS Category | AL2: Cancellation Risk | AM2: Cancelled A Service Within The Last Year
A3: 46197.701 | B3: 46198.595 | C3: 0 | D3: 174.227.87.108 | E3: 100 | F3: 77254 | G3: 1 | H3: 46198.595 | I3: R_3QYw2cwDtcLjPhS | J3: 34.195 | K3: -118.445 | L3: anonymous | M3: EN | N3: 1 | O3: 1 | Y3: 5 | Z3: 4 | AA3: 4 | AB3: 4 | AC3: 4 | AD3: 2 | AE3: 7 | AF3: 2 | AG3: 4 | AH3: 1 | AJ3: =AVERAGE(Y3:AC3) -> 4.2 | AK3: =IF(AE3>=9,"Promoter",IF(AE3>=7,"Passive","Detractor")) -> Passive | AL3: =IF(AG3>=4,"High risk","Low/moderate risk") -> High risk | AM3: =IF(AG3=1,"Yes","No") -> No
A4: 46199.714 | B4: 46199.715 | C4: 0 | D4: 47.157.11.239 | E4: 100 | F4: 119 | G4: 1 | H4: 46199.715 | I4: R_7Ic3QOXZbQv4nf3 | J4: 33.9794 | K4: -118.0609 | L4: anonymous | M4: EN | N4: 1 | O4: 43 | P4: 43 | Q4: 43 | R4: 30 | S4: 1 | T4: 43 | U4: 43 | V4: 2 | W4: 43 | X4: 43 | Y4: 4 | Z4: 3 | AA4: 5 | AB4: 4 | AC4: 4 | AD4: 1 | AE4: 5 | AF4: 2 | AG4: 2 | AH4: 1 | AI4: Prime and Apple have some good shows out right now. That’s about it. | AJ4: =AVERAGE(Y4:AC4) -> 4 | AK4: =IF(AE4>=9,"Promoter",IF(AE4>=7,"Passive","Detractor")) -> Detractor | AL4: =IF(AG4>=4,"High risk","Low/moderate risk") -> Low/moderate risk | AM4: =IF(AG4=1,"Yes","No") -> No
A5: 46199.717 | B5: 46199.718 | C5: 0 | D5: 172.118.234.9 | E5: 100 | F5: 79 | G5: 1 | H5: 46199.718 | I5: R_3ZCSRojYz3GOAY9 | J5: 33.9893 | K5: -118.089 | L5: anonymous | M5: EN | N5: 3 | O5: 1 | P5: 2 | Q5: 43 | R5: 30 | S5: 43 | T5: 30 | U5: 43 | V5: 43 | W5: 43 | X5: 43 | Y5: 5 | Z5: 5 | AA5: 5 | AB5: 5 | AC5: 5 | AD5: 2 | AE5: 7 | AF5: 2 | AG5: 5 | AH5: 2 | AJ5: =AVERAGE(Y5:AC5) -> 5 | AK5: =IF(AE5>=9,"Promoter",IF(AE5>=7,"Passive","Detractor")) -> Passive | AL5: =IF(AG5>=4,"High risk","Low/moderate risk") -> High risk | AM5: =IF(AG5=1,"Yes","No") -> No
A6: 46199.717 | B6: 46199.724 | C6: 0 | D6: 172.56.127.220 | E6: 100 | F6: 557 | G6: 1 | H6: 46199.724 | I6: R_1G6uVLcPuH1Z0Az | J6: 33.9889 | K6: -118.153 | L6: anonymous | M6: EN | N6: 1 | O6: 43 | P6: 43 | Q6: 43 | R6: 43 | S6: 43 | T6: 43 | U6: 43 | V6: 43 | W6: 43 | X6: 1 | Y6: 5 | Z6: 4 | AA6: 3 | AB6: 2 | AC6: 3 | AD6: 1 | AE6: 5 | AF6: 2 | AG6: 2 | AH6: 2 | AI6: I like how convenient it is | AJ6: =AVERAGE(Y6:AC6) -> 3.4 | AK6: =IF(AE6>=9,"Promoter",IF(AE6>=7,"Passive","Detractor")) -> Detractor | AL6: =IF(AG6>=4,"High risk","Low/moderate risk") -> Low/moderate risk | AM6: =IF(AG6=1,"Yes","No") -> No
A7: 46200.053 | B7: 46200.056 | C7: 0 | D7: 68.116.243.14 | E7: 100 | F7: 277 | G7: 1 | H7: 46200.056 | I7: R_7ygw0M6EIOY4CrW | J7: 34.1227 | K7: -118.7573 | L7: anonymous | M7: EN | N7: 1 | O7: 2 | P7: 43 | Q7: 30 | R7: 43 | S7: 43 | T7: 43 | U7: 43 | V7: 43 | W7: 1 | X7: 43 | Y7: 5 | Z7: 4 | AA7: 4 | AB7: 5 | AC7: 3 | AD7: 2 | AE7: 7 | AF7: 1 | AG7: 1 | AH7: 2 | AI7: Replaced Cable TV | AJ7: =AVERAGE(Y7:AC7) -> 4.2 | AK7: =IF(AE7>=9,"Promoter",IF(AE7>=7,"Passive","Detractor")) -> Passive | AL7: =IF(AG7>=4,"High risk","Low/moderate risk") -> Low/moderate risk | AM7: =IF(AG7=1,"Yes","No") -> Yes
A8: 46200.244 | B8: 46200.246 | C8: 0 | D8: 174.219.86.162 | E8: 100 | F8: 179 | G8: 1 | H8: 46200.246 | I8: R_5wo6bASx9q50NIt | J8: 39.884 | K8: -74.9721 | L8: anonymous | M8: EN | N8: 2 | O8: 1 | P8: 2 | Q8: 30 | R8: 43 | S8: 43 | T8: 43 | U8: 43 | V8: 43 | W8: 43 | X8: 43 | Y8: 4 | Z8: 4 | AA8: 4 | AB8: 4 | AC8: 3 | AD8: 2 | AE8: 7 | AF8: 2 | AG8: 4 | AH8: 1 | AI8: Content I want to watch, no commercials, others watching the same shows for us to talk about them | AJ8: =AVERAGE(Y8:AC8) -> 3.8 | AK8: =IF(AE8>=9,"Promoter",IF(AE8>=7,"Passive","Detractor")) -> Passive | AL8: =IF(AG8>=4,"High risk","Low/moderate risk") -> High risk | AM8: =IF(AG8=1,"Yes","No") -> No
A9: 46200.253 | B9: 46200.254 | C9: 0 | D9: 73.233.185.108 | E9: 100 | F9: 101 | G9: 1 | H9: 46200.254 | I9: R_5SvqgRsbh8VQ2MV | J9: 40.207 | K9: -75.0744 | L9: anonymous | M9: EN | N9: 1 | O9: 30 | P9: 1 | Q9: 43 | R9: 43 | S9: 43 | T9: 2 | U9: 43 | V9: 43 | W9: 43 | X9: 43 | Y9: 5 | Z9: 5 | AA9: 5 | AB9: 5 | AC9: 5 | AD9: 3 | AE9: 10 | AF9: 1 | AG9: 2 | AH9: 2 | AI9: It has all the sports games I want to watch | AJ9: =AVERAGE(Y9:AC9) -> 5 | AK9: =IF(AE9>=9,"Promoter",IF(AE9>=7,"Passive","Detractor")) -> Promoter | AL9: =IF(AG9>=4,"High risk","Low/moderate risk") -> Low/moderate risk | AM9: =IF(AG9=1,"Yes","No") -> No
A10: 46200.256 | B10: 46200.257 | C10: 0 | D10: 107.127.13.55 | E10: 100 | F10: 82 | G10: 1 | H10: 46200.257 | I10: R_3ZUNk2hyCuw5ZBf | J10: 39.6635 | K10: -84.2439 | L10: anonymous | M10: EN | N10: 1 | O10: 1 | P10: 2 | Q10: 30 | R10: 43 | S10: 43 | T10: 43 | U10: 43 | V10: 43 | W10: 43 | X10: 43 | Y10: 1 | Z10: 1 | AA10: 3 | AB10: 4 | AC10: 3 | AD10: 1 | AE10: 3 | AF10: 1 | AG10: 5 | AH10: 1 | AI10: Variety of content | AJ10: =AVERAGE(Y10:AC10) -> 2.4 | AK10: =IF(AE10>=9,"Promoter",IF(AE10>=7,"Passive","Detractor")) -> Detractor | AL10: =IF(AG10>=4,"High risk","Low/moderate risk") -> High risk | AM10: =IF(AG10=1,"Yes","No") -> No
A11: 46200.258 | B11: 46200.259 | C11: 0 | D11: 73.230.83.35 | E11: 100 | F11: 80 | G11: 1 | H11: 46200.259 | I11: R_7tyPefbIqpeZzUt | J11: 40.3102 | K11: -76.0388 | L11: anonymous | M11: EN | N11: 1 | O11: 1 | P11: 43 | Q11: 43 | R11: 43 | S11: 43 | T11: 30 | U11: 43 | V11: 43 | W11: 2 | X11: 43 | Y11: 4 | Z11: 4 | AA11: 4 | AB11: 4 | AC11: 4 | AD11: 3 | AE11: 10 | AF11: 2 | AG11: 1 | AH11: 2 | AJ11: =AVERAGE(Y11:AC11) -> 4 | AK11: =IF(AE11>=9,"Promoter",IF(AE11>=7,"Passive","Detractor")) -> Promoter | AL11: =IF(AG11>=4,"High risk","Low/moderate risk") -> Low/moderate risk | AM11: =IF(AG11=1,"Yes","No") -> Yes
A12: 46200.261 | B12: 46200.262 | C12: 0 | D12: 107.222.119.137 | E12: 100 | F12: 122 | G12: 1 | H12: 46200.262 | I12: R_54ejdoXRz9glW4V | J12: 37.7548 | K12: -84.2985 | L12: anonymous | M12: EN | N12: 1 | O12: 1 | P12: 43 | Q12: 43 | R12: 2 | S12: 30 | T12: 43 | U12: 43 | V12: 43 | W12: 43 | X12: 43 | Y12: 5 | Z12: 5 | AA12: 5 | AB12: 4 | AC12: 3 | AD12: 2 | AE12: 8 | AF12: 2 | AG12: 4 | AH12: 1 | AJ12: =AVERAGE(Y12:AC12) -> 4.4 | AK12: =IF(AE12>=9,"Promoter",IF(AE12>=7,"Passive","Detractor")) -> Passive | AL12: =IF(AG12>=4,"High risk","Low/moderate risk") -> High risk | AM12: =IF(AG12=1,"Yes","No") -> No
A13: 46200.263 | B13: 46200.265 | C13: 0 | D13: 46.110.82.38 | E13: 100 | F13: 170 | G13: 1 | H13: 46200.265 | I13: R_3RAxeVk1gybD4UV | J13: 41.5749 | K13: -90.6087 | L13: anonymous | M13: EN | N13: 1 | O13: 1 | P13: 43 | Q13: 2 | R13: 43 | S13: 30 | T13: 43 | U13: 43 | V13: 43 | W13: 43 | X13: 43 | Y13: 5 | Z13: 5 | AA13: 5 | AB13: 4 | AC13: 4 | AD13: 2 | AE13: 8 | AF13: 1 | AG13: 2 | AH13: 2 | AJ13: =AVERAGE(Y13:AC13) -> 4.6 | AK13: =IF(AE13>=9,"Promoter",IF(AE13>=7,"Passive","Detractor")) -> Passive | AL13: =IF(AG13>=4,"High risk","Low/moderate risk") -> Low/moderate risk | AM13: =IF(AG13=1,"Yes","No") -> No
A14: 46200.263 | B14: 46200.267 | C14: 0 | D14: 71.92.166.245 | E14: 100 | F14: 351 | G14: 1 | H14: 46200.267 | I14: R_741Vhs9459RUFHm | J14: 39.6261 | K14: -119.6996 | L14: anonymous | M14: EN | N14: 1 | O14: 30 | P14: 43 | Q14: 43 | R14: 43 | S14: 1 | T14: 43 | U14: 2 | V14: 43 | W14: 43 | X14: 43 | Y14: 5 | Z14: 5 | AA14: 5 | AB14: 2 | AC14: 3 | AD14: 2 | AE14: 8 | AF14: 2 | AG14: 4 | AH14: 1 | AI14: It has the best variety for my interests, and secondly it is seamlessly integrated to my Amazon usage making it feel like a package deal, finally it feels like a good value for what comes for free and I appreciate that items for purchase are available and reasonable. | AJ14: =AVERAGE(Y14:AC14) -> 4 | AK14: =IF(AE14>=9,"Promoter",IF(AE14>=7,"Passive","Detractor")) -> Passive | AL14: =IF(AG14>=4,"High risk","Low/moderate risk") -> High risk | AM14: =IF(AG14=1,"Yes","No") -> No
A15: 46200.266 | B15: 46200.267 | C15: 0 | D15: 76.150.200.50 | E15: 100 | F15: 152 | G15: 1 | H15: 46200.267 | I15: R_72ZSk6QvARSSrvj | J15: 42.2739 | K15: -89.0474 | L15: anonymous | M15: EN | N15: 2 | O15: 30 | P15: 1 | Q15: 2 | R15: 43 | S15: 30 | T15: 43 | U15: 43 | V15: 43 | W15: 43 | X15: 43 | Y15: 4 | Z15: 4 | AA15: 3 | AB15: 3 | AC15: 3 | AD15: 2 | AE15: 7 | AF15: 1 | AG15: 3 | AH15: 1 | AJ15: =AVERAGE(Y15:AC15) -> 3.4 | AK15: =IF(AE15>=9,"Promoter",IF(AE15>=7,"Passive","Detractor")) -> Passive | AL15: =IF(AG15>=4,"High risk","Low/moderate risk") -> Low/moderate risk | AM15: =IF(AG15=1,"Yes","No") -> No
A16: 46200.268 | B16: 46200.269 | C16: 0 | D16: 98.115.250.207 | E16: 100 | F16: 102 | G16: 1 | H16: 46200.269 | I16: R_5q3TSQI6QGhhCzT | J16: 40.2163 | K16: -74.7724 | L16: anonymous | M16: EN | N16: 1 | O16: 1 | P16: 43 | Q16: 2 | R16: 30 | S16: 43 | T16: 43 | U16: 43 | V16: 43 | W16: 43 | X16: 43 | Y16: 5 | Z16: 5 | AA16: 5 | AB16: 4 | AC16: 4 | AD16: 3 | AE16: 10 | AF16: 2 | AG16: 2 | AH16: 2 | AI16: I have kids who enjoy most of the content | AJ16: =AVERAGE(Y16:AC16) -> 4.6 | AK16: =IF(AE16>=9,"Promoter",IF(AE16>=7,"Passive","Detractor")) -> Promoter | AL16: =IF(AG16>=4,"High risk","Low/moderate risk") -> Low/moderate risk | AM16: =IF(AG16=1,"Yes","No") -> No
A17: 46200.277 | B17: 46200.28 | C17: 0 | D17: 68.95.99.9 | E17: 100 | F17: 212 | G17: 1 | H17: 46200.28 | I17: R_674sTQixyebtHsl | J17: 35.2426 | K17: -80.741 | L17: anonymous | M17: EN | N17: 1 | O17: 1 | P17: 43 | Q17: 43 | R17: 43 | S17: 30 | T17: 43 | U17: 43 | V17: 2 | W17: 43 | X17: 43 | Y17: 5 | Z17: 5 | AA17: 5 | AB17: 5 | AC17: 5 | AD17: 3 | AE17: 10 | AF17: 2 | AG17: 1 | AH17: 1 | AI17: Frequency in new material and renewed series | AJ17: =AVERAGE(Y17:AC17) -> 5 | AK17: =IF(AE17>=9,"Promoter",IF(AE17>=7,"Passive","Detractor")) -> Promoter | AL17: =IF(AG17>=4,"High risk","Low/moderate risk") -> Low/moderate risk | AM17: =IF(AG17=1,"Yes","No") -> Yes
A18: 46200.297 | B18: 46200.298 | C18: 0 | D18: 166.198.251.117 | E18: 100 | F18: 117 | G18: 1 | H18: 46200.298 | I18: R_7I6sxMMUhTZTXd0 | J18: 39.9587 | K18: -82.9987 | L18: anonymous | M18: EN | N18: 1 | O18: 1 | P18: 30 | Q18: 2 | R18: 43 | S18: 43 | T18: 43 | U18: 43 | V18: 43 | W18: 43 | X18: 43 | Y18: 4 | Z18: 4 | AA18: 4 | AB18: 3 | AC18: 4 | AD18: 2 | AE18: 7 | AF18: 1 | AG18: 2 | AH18: 1 | AJ18: =AVERAGE(Y18:AC18) -> 3.8 | AK18: =IF(AE18>=9,"Promoter",IF(AE18>=7,"Passive","Detractor")) -> Passive | AL18: =IF(AG18>=4,"High risk","Low/moderate risk") -> Low/moderate risk | AM18: =IF(AG18=1,"Yes","No") -> No
A19: 46200.303 | B19: 46200.304 | C19: 0 | D19: 174.228.98.187 | E19: 100 | F19: 98 | G19: 1 | H19: 46200.304 | I19: R_6M4Bm4UdqQZ7cGe | J19: 41.8502 | K19: -87.6736 | L19: anonymous | M19: EN | N19: 1 | O19: 2 | P19: 30 | Q19: 43 | R19: 43 | S19: 43 | T19: 43 | U19: 43 | V19: 43 | W19: 1 | X19: 43 | Y19: 5 | Z19: 4 | AA19: 4 | AB19: 2 | AC19: 4 | AD19: 3 | AE19: 9 | AF19: 1 | AG19: 4 | AH19: 1 | AI19: Cost | AJ19: =AVERAGE(Y19:AC19) -> 3.8 | AK19: =IF(AE19>=9,"Promoter",IF(AE19>=7,"Passive","Detractor")) -> Promoter | AL19: =IF(AG19>=4,"High risk","Low/moderate risk") -> High risk | AM19: =IF(AG19=1,"Yes","No") -> No
A20: 46200.316 | B20: 46200.318 | C20: 0 | D20: 69.129.201.139 | E20: 100 | F20: 133 | G20: 1 | H20: 46200.318 | I20: R_6WBwbe6eGhcNDO9 | J20: 42.9958 | K20: -89.5499 | L20: anonymous | M20: EN | N20: 1 | O20: 43 | P20: 43 | Q20: 43 | R20: 1 | S20: 43 | T20: 30 | U20: 43 | V20: 2 | W20: 43 | X20: 43 | Y20: 5 | Z20: 4 | AA20: 3 | AB20: 4 | AC20: 2 | AD20: 1 | AE20: 6 | AF20: 2 | AG20: 5 | AH20: 1 | AI20: Options and movies | AJ20: =AVERAGE(Y20:AC20) -> 3.6 | AK20: =IF(AE20>=9,"Promoter",IF(AE20>=7,"Passive","Detractor")) -> Detractor | AL20: =IF(AG20>=4,"High risk","Low/moderate risk") -> High risk | AM20: =IF(AG20=1,"Yes","No") -> No
A21: 46200.321 | B21: 46200.324 | C21: 0 | D21: 45.50.19.40 | E21: 100 | F21: 243 | G21: 1 | H21: 46200.324 | I21: R_63UXNUwfBX2rEzr | J21: 33.93 | K21: -117.9477 | L21: anonymous | M21: EN | N21: 1 | O21: 2 | S21: 1 | T21: 43 | U21: 30 | V21: 43 | Y21: 5 | Z21: 4 | AA21: 4 | AB21: 4 | AC21: 3 | AD21: 3 | AE21: 9 | AF21: 2 | AG21: 2 | AH21: 2 | AI21: Wide variety of great programs, movies | AJ21: =AVERAGE(Y21:AC21) -> 4 | AK21: =IF(AE21>=9,"Promoter",IF(AE21>=7,"Passive","Detractor")) -> Promoter | AL21: =IF(AG21>=4,"High risk","Low/moderate risk") -> Low/moderate risk | AM21: =IF(AG21=1,"Yes","No") -> No
A22: 46200.329 | B22: 46200.331 | C22: 0 | D22: 98.187.137.233 | E22: 100 | F22: 139 | G22: 1 | H22: 46200.331 | I22: R_31cSuUcibJ2P67v | J22: 36.1805 | K22: -94.5304 | L22: anonymous | M22: EN | N22: 1 | O22: 30 | P22: 43 | Q22: 1 | R22: 43 | S22: 43 | T22: 2 | U22: 43 | V22: 43 | W22: 43 | X22: 43 | Y22: 5 | Z22: 5 | AA22: 5 | AB22: 3 | AC22: 5 | AD22: 3 | AE22: 10 | AF22: 1 | AG22: 5 | AH22: 1 | AI22: It has content that I love. It isn't glitchy | AJ22: =AVERAGE(Y22:AC22) -> 4.6 | AK22: =IF(AE22>=9,"Promoter",IF(AE22>=7,"Passive","Detractor")) -> Promoter | AL22: =IF(AG22>=4,"High risk","Low/moderate risk") -> High risk | AM22: =IF(AG22=1,"Yes","No") -> No
A23: 46200.352 | B23: 46200.355 | C23: 0 | D23: 174.218.82.218 | E23: 100 | F23: 235 | G23: 1 | H23: 46200.355 | I23: R_6qId9hle9eQrLEZ | J23: 34.0587 | K23: -118.2781 | L23: anonymous | M23: EN | N23: 1 | O23: 30 | P23: 43 | Q23: 43 | R23: 43 | S23: 2 | T23: 43 | U23: 43 | V23: 43 | W23: 1 | X23: 43 | Y23: 5 | Z23: 5 | AA23: 5 | AB23: 5 | AC23: 5 | AD23: 3 | AE23: 10 | AF23: 1 | AG23: 2 | AH23: 2 | AJ23: =AVERAGE(Y23:AC23) -> 5 | AK23: =IF(AE23>=9,"Promoter",IF(AE23>=7,"Passive","Detractor")) -> Promoter | AL23: =IF(AG23>=4,"High risk","Low/moderate risk") -> Low/moderate risk | AM23: =IF(AG23=1,"Yes","No") -> No
A24: 46200.357 | B24: 46200.359 | C24: 0 | D24: 166.194.188.73 | E24: 100 | F24: 146 | G24: 1 | H24: 46200.359 | I24: R_7S2dmfcImtPm61L | J24: 40.1586 | K24: -75.282 | L24: anonymous | M24: EN | N24: 1 | O24: 1 | P24: 30 | Q24: 43 | R24: 43 | S24: 2 | T24: 43 | U24: 43 | V24: 43 | W24: 43 | X24: 43 | Y24: 5 | Z24: 4 | AA24: 4 | AB24: 3 | AC24: 3 | AD24: 2 | AE24: 8 | AF24: 2 | AG24: 4 | AH24: 1 | AI24: Ease of use | AJ24: =AVERAGE(Y24:AC24) -> 3.8 | AK24: =IF(AE24>=9,"Promoter",IF(AE24>=7,"Passive","Detractor")) -> Passive | AL24: =IF(AG24>=4,"High risk","Low/moderate risk") -> High risk | AM24: =IF(AG24=1,"Yes","No") -> No
A25: 46200.382 | B25: 46200.384 | C25: 0 | D25: 96.8.181.44 | E25: 100 | F25: 112 | G25: 1 | H25: 46200.384 | I25: R_56mwUxLsllClm0k | J25: 29.7026 | K25: -98.4759 | L25: anonymous | M25: EN | N25: 1 | O25: 1 | P25: 2 | Q25: 30 | R25: 43 | S25: 43 | V25: 43 | Y25: 5 | Z25: 4 | AA25: 4 | AB25: 2 | AC25: 3 | AD25: 2 | AE25: 7 | AF25: 1 | AG25: 1 | AH25: 2 | AI25: New shows and movies | AJ25: =AVERAGE(Y25:AC25) -> 3.6 | AK25: =IF(AE25>=9,"Promoter",IF(AE25>=7,"Passive","Detractor")) -> Passive | AL25: =IF(AG25>=4,"High risk","Low/moderate risk") -> Low/moderate risk | AM25: =IF(AG25=1,"Yes","No") -> Yes
A26: 46200.419 | B26: 46200.421 | C26: 0 | D26: 166.194.143.48 | E26: 100 | F26: 95 | G26: 1 | H26: 46200.421 | I26: R_3Vm4Mn3XmtQFOBW | J26: 33.4683 | K26: -112.0549 | L26: anonymous | M26: EN | N26: 1 | O26: 1 | P26: 2 | Q26: 43 | R26: 43 | S26: 30 | T26: 43 | U26: 43 | V26: 43 | W26: 43 | X26: 43 | Y26: 5 | Z26: 4 | AA26: 4 | AB26: 3 | AC26: 3 | AD26: 2 | AE26: 7 | AF26: 1 | AG26: 3 | AH26: 1 | AJ26: =AVERAGE(Y26:AC26) -> 3.8 | AK26: =IF(AE26>=9,"Promoter",IF(AE26>=7,"Passive","Detractor")) -> Passive | AL26: =IF(AG26>=4,"High risk","Low/moderate risk") -> Low/moderate risk | AM26: =IF(AG26=1,"Yes","No") -> No
A27: 46200.454 | B27: 46200.457 | C27: 0 | D27: 174.233.182.53 | E27: 100 | F27: 193 | G27: 1 | H27: 46200.457 | I27: R_3hxT0Fa09x9ob3E | J27: 41.923 | K27: -87.7531 | L27: anonymous | M27: EN | N27: 3 | O27: 43 | P27: 43 | Q27: 43 | R27: 43 | S27: 2 | T27: 1 | U27: 30 | V27: 43 | W27: 43 | X27: 43 | Y27: 4 | Z27: 4 | AA27: 4 | AB27: 2 | AC27: 4 | AD27: 2 | AE27: 7 | AF27: 2 | AG27: 2 | AH27: 2 | AJ27: =AVERAGE(Y27:AC27) -> 3.6 | AK27: =IF(AE27>=9,"Promoter",IF(AE27>=7,"Passive","Detractor")) -> Passive | AL27: =IF(AG27>=4,"High risk","Low/moderate risk") -> Low/moderate risk | AM27: =IF(AG27=1,"Yes","No") -> No
A28: 46200.459 | B28: 46200.46 | C28: 0 | D28: 199.33.97.219 | E28: 100 | F28: 122 | G28: 1 | H28: 46200.46 | I28: R_62VmvvQJeNs4z42 | J28: 36.0154 | K28: -83.4149 | L28: anonymous | M28: EN | N28: 1 | O28: 1 | P28: 2 | Q28: 30 | R28: 43 | S28: 43 | T28: 43 | U28: 43 | V28: 43 | W28: 43 | X28: 43 | Y28: 5 | Z28: 5 | AA28: 5 | AB28: 3 | AC28: 4 | AD28: 2 | AE28: 7 | AF28: 1 | AG28: 3 | AH28: 1 | AI28: Most options that I enjoy | AJ28: =AVERAGE(Y28:AC28) -> 4.4 | AK28: =IF(AE28>=9,"Promoter",IF(AE28>=7,"Passive","Detractor")) -> Passive | AL28: =IF(AG28>=4,"High risk","Low/moderate risk") -> Low/moderate risk | AM28: =IF(AG28=1,"Yes","No") -> No
A29: 46200.507 | B29: 46200.512 | C29: 0 | D29: 45.50.19.40 | E29: 100 | F29: 393 | G29: 1 | H29: 46200.512 | I29: R_1QfFOKZrH3G9PKo | J29: 33.93 | K29: -117.9477 | L29: anonymous | M29: EN | N29: 2 | O29: 30 | P29: 43 | Q29: 43 | R29: 43 | S29: 1 | T29: 43 | U29: 2 | V29: 43 | W29: 43 | X29: 43 | Y29: 1 | Z29: 1 | AA29: 1 | AB29: 1 | AC29: 1 | AD29: 3 | AE29: 10 | AF29: 1 | AG29: 3 | AH29: 2 | AJ29: =AVERAGE(Y29:AC29) -> 1 | AK29: =IF(AE29>=9,"Promoter",IF(AE29>=7,"Passive","Detractor")) -> Promoter | AL29: =IF(AG29>=4,"High risk","Low/moderate risk") -> Low/moderate risk | AM29: =IF(AG29=1,"Yes","No") -> No
A30: 46200.51 | B30: 46200.512 | C30: 0 | D30: 172.56.221.80 | E30: 100 | F30: 192 | G30: 1 | H30: 46200.512 | I30: R_6Qrk0Vn5jyvsyZb | J30: 40.0598 | K30: -75.1448 | L30: anonymous | M30: EN | N30: 1 | O30: 43 | P30: 43 | Q30: 43 | R30: 1 | S30: 2 | T30: 43 | U30: 1 | V30: 43 | W30: 43 | X30: 43 | Y30: 5 | Z30: 5 | AA30: 5 | AB30: 3 | AC30: 5 | AD30: 3 | AE30: 10 | AF30: 1 | AG30: 3 | AH30: 2 | AJ30: =AVERAGE(Y30:AC30) -> 4.6 | AK30: =IF(AE30>=9,"Promoter",IF(AE30>=7,"Passive","Detractor")) -> Promoter | AL30: =IF(AG30>=4,"High risk","Low/moderate risk") -> Low/moderate risk | AM30: =IF(AG30=1,"Yes","No") -> No
A31: 46200.517 | B31: 46200.518 | C31: 0 | D31: 46.110.178.68 | E31: 100 | F31: 124 | G31: 1 | H31: 46200.518 | I31: R_5eeqaPh4tM7RVBA | J31: 41.4943 | K31: -90.5001 | L31: anonymous | M31: EN | N31: 1 | O31: 1 | P31: 43 | Q31: 43 | R31: 30 | S31: 43 | T31: 43 | U31: 43 | V31: 2 | W31: 43 | X31: 43 | Y31: 4 | Z31: 4 | AA31: 4 | AB31: 3 | AC31: 3 | AD31: 2 | AE31: 7 | AF31: 2 | AG31: 4 | AH31: 2 | AI31: Variety of options that rotate and no ads | AJ31: =AVERAGE(Y31:AC31) -> 3.6 | AK31: =IF(AE31>=9,"Promoter",IF(AE31>=7,"Passive","Detractor")) -> Passive | AL31: =IF(AG31>=4,"High risk","Low/moderate risk") -> High risk | AM31: =IF(AG31=1,"Yes","No") -> No
A32: 46200.531 | B32: 46200.533 | C32: 0 | D32: 96.235.170.163 | E32: 100 | F32: 112 | G32: 1 | H32: 46200.533 | I32: R_1kjrMugsCpQsw1j | J32: 40.2381 | K32: -74.7822 | L32: anonymous | M32: EN | N32: 1 | O32: 30 | P32: 43 | Q32: 2 | R32: 43 | S32: 1 | T32: 43 | U32: 43 | V32: 43 | W32: 43 | X32: 43 | Y32: 5 | Z32: 4 | AA32: 3 | AB32: 3 | AC32: 3 | AD32: 1 | AE32: 5 | AF32: 3 | AG32: 4 | AH32: 1 | AJ32: =AVERAGE(Y32:AC32) -> 3.6 | AK32: =IF(AE32>=9,"Promoter",IF(AE32>=7,"Passive","Detractor")) -> Detractor | AL32: =IF(AG32>=4,"High risk","Low/moderate risk") -> High risk | AM32: =IF(AG32=1,"Yes","No") -> No
A33: 46200.545 | B33: 46200.547 | C33: 0 | D33: 174.65.124.151 | E33: 100 | F33: 200 | G33: 1 | H33: 46200.547 | I33: R_1nJhS6UMRhoehhW | J33: 33.1097 | K33: -117.067 | L33: anonymous | M33: EN | N33: 1 | O33: 43 | P33: 1 | Q33: 43 | R33: 30 | S33: 43 | T33: 2 | U33: 2 | V33: 43 | W33: 43 | X33: 43 | Y33: 4 | Z33: 3 | AA33: 3 | AB33: 2 | AC33: 2 | AD33: 1 | AE33: 3 | AF33: 3 | AG33: 5 | AH33: 1 | AI33: The show I like is on it | AJ33: =AVERAGE(Y33:AC33) -> 2.8 | AK33: =IF(AE33>=9,"Promoter",IF(AE33>=7,"Passive","Detractor")) -> Detractor | AL33: =IF(AG33>=4,"High risk","Low/moderate risk") -> High risk | AM33: =IF(AG33=1,"Yes","No") -> No
A34: 46200.546 | B34: 46200.55 | C34: 0 | D34: 68.252.20.239 | E34: 100 | F34: 394 | G34: 1 | H34: 46200.551 | I34: R_1NVEsiRhTQYOGq1 | J34: 26.4141 | K34: -80.0972 | L34: anonymous | M34: EN | N34: 1 | O34: 2 | P34: 43 | Q34: 43 | R34: 1 | S34: 43 | T34: 43 | U34: 43 | V34: 30 | W34: 43 | X34: 43 | Y34: 5 | Z34: 5 | AA34: 5 | AB34: 5 | AC34: 5 | AD34: 3 | AE34: 10 | AF34: 2 | AG34: 1 | AH34: 2 | AJ34: =AVERAGE(Y34:AC34) -> 5 | AK34: =IF(AE34>=9,"Promoter",IF(AE34>=7,"Passive","Detractor")) -> Promoter | AL34: =IF(AG34>=4,"High risk","Low/moderate risk") -> Low/moderate risk | AM34: =IF(AG34=1,"Yes","No") -> Yes
A35: 46200.551 | B35: 46200.551 | C35: 0 | D35: 125.103.25.178 | E35: 100 | F35: 69 | G35: 1 | H35: 46200.551 | I35: R_4ikSj029XCm4KgV | J35: 35.6017 | K35: 139.7431 | L35: anonymous | M35: EN | N35: 1 | O35: 1 | P35: 2 | Q35: 43 | R35: 43 | S35: 30 | T35: 43 | U35: 43 | V35: 43 | W35: 43 | X35: 43 | Y35: 1 | Z35: 1 | AA35: 1 | AB35: 3 | AC35: 3 | AD35: 3 | AE35: 10 | AF35: 1 | AG35: 4 | AH35: 1 | AJ35: =AVERAGE(Y35:AC35) -> 1.8 | AK35: =IF(AE35>=9,"Promoter",IF(AE35>=7,"Passive","Detractor")) -> Promoter | AL35: =IF(AG35>=4,"High risk","Low/moderate risk") -> High risk | AM35: =IF(AG35=1,"Yes","No") -> No
A36: 46200.552 | B36: 46200.554 | C36: 0 | D36: 68.252.20.239 | E36: 100 | F36: 183 | G36: 1 | H36: 46200.554 | I36: R_5rw7fSu7o833noW | J36: 26.4141 | K36: -80.0972 | L36: anonymous | M36: EN | N36: 1 | O36: 1 | P36: 30 | Q36: 30 | R36: 2 | S36: 43 | T36: 30 | U36: 30 | V36: 2 | W36: 43 | X36: 43 | Y36: 3 | Z36: 3 | AA36: 3 | AB36: 3 | AC36: 3 | AD36: 1 | AE36: 6 | AF36: 1 | AG36: 3 | AH36: 2 | AI36: Good movies | AJ36: =AVERAGE(Y36:AC36) -> 3 | AK36: =IF(AE36>=9,"Promoter",IF(AE36>=7,"Passive","Detractor")) -> Detractor | AL36: =IF(AG36>=4,"High risk","Low/moderate risk") -> Low/moderate risk | AM36: =IF(AG36=1,"Yes","No") -> No
A37: 46200.602 | B37: 46200.604 | C37: 0 | D37: 70.95.14.154 | E37: 100 | F37: 125 | G37: 1 | H37: 46200.604 | I37: R_6mVqrmvvNS4opfb | J37: 32.9164 | K37: -117.1393 | L37: anonymous | M37: EN | N37: 2 | O37: 1 | P37: 43 | Q37: 43 | R37: 30 | S37: 43 | T37: 2 | U37: 43 | V37: 43 | W37: 43 | X37: 43 | Y37: 5 | Z37: 5 | AA37: 5 | AB37: 5 | AC37: 5 | AD37: 3 | AE37: 10 | AF37: 1 | AG37: 2 | AH37: 2 | AJ37: =AVERAGE(Y37:AC37) -> 5 | AK37: =IF(AE37>=9,"Promoter",IF(AE37>=7,"Passive","Detractor")) -> Promoter | AL37: =IF(AG37>=4,"High risk","Low/moderate risk") -> Low/moderate risk | AM37: =IF(AG37=1,"Yes","No") -> No
A38: 46200.569 | B38: 46200.664 | C38: 0 | D38: 73.165.241.59 | E38: 100 | F38: 8183 | G38: 1 | H38: 46200.664 | I38: R_7Su948qzfQifJnT | J38: 40.0146 | K38: -75.7136 | L38: anonymous | M38: EN | N38: 1 | O38: 43 | P38: 30 | Q38: 43 | R38: 43 | S38: 2 | T38: 43 | U38: 43 | V38: 43 | W38: 1 | X38: 43 | Y38: 3 | Z38: 3 | AA38: 4 | AB38: 3 | AC38: 3 | AD38: 1 | AE38: 6 | AF38: 1 | AG38: 2 | AH38: 2 | AI38: Affordability | AJ38: =AVERAGE(Y38:AC38) -> 3.2 | AK38: =IF(AE38>=9,"Promoter",IF(AE38>=7,"Passive","Detractor")) -> Detractor | AL38: =IF(AG38>=4,"High risk","Low/moderate risk") -> Low/moderate risk | AM38: =IF(AG38=1,"Yes","No") -> No
A39: 46200.707 | B39: 46200.708 | C39: 0 | D39: 71.188.87.72 | E39: 100 | F39: 146 | G39: 1 | H39: 46200.708 | I39: R_5soXWh4QWeArnpx | J39: 40.3344 | K39: -74.795 | L39: anonymous | M39: EN | N39: 1 | O39: 43 | P39: 1 | Q39: 43 | R39: 2 | S39: 30 | T39: 43 | U39: 43 | V39: 43 | W39: 43 | X39: 43 | Y39: 5 | Z39: 1 | AA39: 5 | AB39: 5 | AC39: 5 | AD39: 3 | AE39: 10 | AF39: 1 | AG39: 1 | AH39: 2 | AJ39: =AVERAGE(Y39:AC39) -> 4.2 | AK39: =IF(AE39>=9,"Promoter",IF(AE39>=7,"Passive","Detractor")) -> Promoter | AL39: =IF(AG39>=4,"High risk","Low/moderate risk") -> Low/moderate risk | AM39: =IF(AG39=1,"Yes","No") -> Yes

Sheet Cleaned Data
A1: StartDate | B1: EndDate | C1: Status | D1: IPAddress | E1: Progress | F1: Duration (in seconds) | G1: Finished | H1: RecordedDate | I1: ResponseId | J1: LocationLatitude | K1: LocationLongitude | L1: DistributionChannel | M1: UserLanguage | N1: Q1 | O1: Q2_1 | P1: Q2_2 | Q1: Q2_3 | R1: Q2_4 | S1: Q2_5 | T1: Q2_6 | U1: Q2_7 | V1: Q2_8 | W1: Q2_9 | X1: Q2_10 | Y1: Q3_1 | Z1: Q3_2 | AA1: Q3_3 | AB1: Q3_4 | AC1: Q3_5 | AD1: Q4_NPS_GROUP | AE1: Q4 | AF1: Q5 | AG1: Q6 | AH1: Q7 | AI1: Q8
A2: Start Date | B2: End Date | C2: Response Type | D2: IP Address | E2: Progress | F2: Duration (in seconds) | G2: Finished | H2: Recorded Date | I2: Response ID | J2: Location Latitude | K2: Location Longitude | L2: Distribution Channel | M2: User Language | N2: Which statement best describes your role in streaming service decisions for your household? | O2: Please rank each streaming service based on how often you use it. Select First Most Used Service for the streaming service you use the most. Select Second Most Used Service for the service you use second most. Select Third Most Used Service for the service you use third most. For all other services, select Other (Not in top 3). - Netflix | P2: Please rank each streaming service based on how often you use it. Select First Most Used Service for the streaming service you use the most. Select Second Most Used Service for the service you use second most. Select Third Most Used Service for the service you use third most. For all other services, select Other (Not in top 3). - Hulu | Q2: Please rank each streaming service based on how often you use it. Select First Most Used Service for the streaming service you use the most. Select Second Most Used Service for the service you use second most. Select Third Most Used Service for the service you use third most. For all other services, select Other (Not in top 3). - Disney+ | R2: Please rank each streaming service based on how often you use it. Select First Most Used Service for the streaming service you use the most. Select Second Most Used Service for the service you use second most. Select Third Most Used Service for the service you use third most. For all other services, select Other (Not in top 3). - Max | S2: Please rank each streaming service based on how often you use it. Select First Most Used Service for the streaming service you use the most. Select Second Most Used Service for the service you use second most. Select Third Most Used Service for the service you use third most. For all other services, select Other (Not in top 3). - Prime Video | T2: Please rank each streaming service based on how often you use it. Select First Most Used Service for the streaming service you use the most. Select Second Most Used Service for the service you use second most. Select Third Most Used Service for the service you use third most. For all other services, select Other (Not in top 3). - Peacock | U2: Please rank each streaming service based on how often you use it. Select First Most Used Service for the streaming service you use the most. Select Second Most Used Service for the service you use second most. Select Third Most Used Service for the service you use third most. For all other services, select Other (Not in top 3). - Paramount+ | V2: Please rank each streaming service based on how often you use it. Select First Most Used Service for the streaming service you use the most. Select Second Most Used Service for the service you use second most. Select Third Most Used Service for the service you use third most. For all other services, select Other (Not in top 3). - Apple TV+ | W2: Please rank each streaming service based on how often you use it. Select First Most Used Service for the streaming service you use the most. Select Second Most Used Service for the service you use second most. Select Third Most Used Service for the service you use third most. For all other services, select Other (Not in top 3). - YouTube TV | X2: Please rank each streaming service based on how often you use it. Select First Most Used Service for the streaming service you use the most. Select Second Most Used Service for the service you use second most. Select Third Most Used Service for the service you use third most. For all other services, select Other (Not in top 3). - Other | Y2: Please indicate your level of agreement with the following statements about the streaming service you use most often. - I intend to keep using this streaming service. | Z2: Please indicate your level of agreement with the following statements about the streaming service you use most often. - This streaming service would be one of my first choices. | AA2: Please indicate your level of agreement with the following statements about the streaming service you use most often. - I would recommend this streaming service to others. | AB2: Please indicate your level of agreement with the following statements about the streaming service you use most often. - I would not easily switch to a competing streaming service. | AC2: Please indicate your level of agreement with the following statements about the streaming service you use most often. - I trust this streaming service. | AD2: How likely are you to recommend the streaming service you use most often to a friend or colleague? - Group | AE2: How likely are you to recommend the streaming service you use most often to a friend or colleague? | AF2: In the past 6 months, how often have you used the streaming service you ranked as #1? | AG2: How likely are you to cancel at least one streaming service in the next 6 months? | AH2: Have you canceled a streaming service within the past year? | AI2: What is the main reason you would continue using the streaming service you ranked as your first most used service? (Optional)
A3: 46197.701 | B3: 46198.595 | C3: 0 | D3: 174.227.87.108 | E3: 100 | F3: 77254 | G3: 1 | H3: 46198.595 | I3: R_3QYw2cwDtcLjPhS | J3: 34.195 | K3: -118.445 | L3: anonymous | M3: EN | N3: 1 | O3: 1 | Y3: 5 | Z3: 4 | AA3: 4 | AB3: 4 | AC3: 4 | AD3: 2 | AE3: 7 | AF3: 2 | AG3: 4 | AH3: 1
A4: 46199.714 | B4: 46199.715 | C4: 0 | D4: 47.157.11.239 | E4: 100 | F4: 119 | G4: 1 | H4: 46199.715 | I4: R_7Ic3QOXZbQv4nf3 | J4: 33.9794 | K4: -118.0609 | L4: anonymous | M4: EN | N4: 1 | O4: 43 | P4: 43 | Q4: 43 | R4: 30 | S4: 1 | T4: 43 | U4: 43 | V4: 2 | W4: 43 | X4: 43 | Y4: 4 | Z4: 3 | AA4: 5 | AB4: 4 | AC4: 4 | AD4: 1 | AE4: 5 | AF4: 2 | AG4: 2 | AH4: 1 | AI4: Prime and Apple have some good shows out right now. That’s about it.
A5: 46199.717 | B5: 46199.718 | C5: 0 | D5: 172.118.234.9 | E5: 100 | F5: 79 | G5: 1 | H5: 46199.718 | I5: R_3ZCSRojYz3GOAY9 | J5: 33.9893 | K5: -118.089 | L5: anonymous | M5: EN | N5: 3 | O5: 1 | P5: 2 | Q5: 43 | R5: 30 | S5: 43 | T5: 30 | U5: 43 | V5: 43 | W5: 43 | X5: 43 | Y5: 5 | Z5: 5 | AA5: 5 | AB5: 5 | AC5: 5 | AD5: 2 | AE5: 7 | AF5: 2 | AG5: 5 | AH5: 2
A6: 46199.717 | B6: 46199.724 | C6: 0 | D6: 172.56.127.220 | E6: 100 | F6: 557 | G6: 1 | H6: 46199.724 | I6: R_1G6uVLcPuH1Z0Az | J6: 33.9889 | K6: -118.153 | L6: anonymous | M6: EN | N6: 1 | O6: 43 | P6: 43 | Q6: 43 | R6: 43 | S6: 43 | T6: 43 | U6: 43 | V6: 43 | W6: 43 | X6: 1 | Y6: 5 | Z6: 4 | AA6: 3 | AB6: 2 | AC6: 3 | AD6: 1 | AE6: 5 | AF6: 2 | AG6: 2 | AH6: 2 | AI6: I like how convenient it is
A7: 46200.053 | B7: 46200.056 | C7: 0 | D7: 68.116.243.14 | E7: 100 | F7: 277 | G7: 1 | H7: 46200.056 | I7: R_7ygw0M6EIOY4CrW | J7: 34.1227 | K7: -118.7573 | L7: anonymous | M7: EN | N7: 1 | O7: 2 | P7: 43 | Q7: 30 | R7: 43 | S7: 43 | T7: 43 | U7: 43 | V7: 43 | W7: 1 | X7: 43 | Y7: 5 | Z7: 4 | AA7: 4 | AB7: 5 | AC7: 3 | AD7: 2 | AE7: 7 | AF7: 1 | AG7: 1 | AH7: 2 | AI7: Replaced Cable TV
A8: 46200.244 | B8: 46200.246 | C8: 0 | D8: 174.219.86.162 | E8: 100 | F8: 179 | G8: 1 | H8: 46200.246 | I8: R_5wo6bASx9q50NIt | J8: 39.884 | K8: -74.9721 | L8: anonymous | M8: EN | N8: 2 | O8: 1 | P8: 2 | Q8: 30 | R8: 43 | S8: 43 | T8: 43 | U8: 43 | V8: 43 | W8: 43 | X8: 43 | Y8: 4 | Z8: 4 | AA8: 4 | AB8: 4 | AC8: 3 | AD8: 2 | AE8: 7 | AF8: 2 | AG8: 4 | AH8: 1 | AI8: Content I want to watch, no commercials, others watching the same shows for us to talk about them
A9: 46200.253 | B9: 46200.254 | C9: 0 | D9: 73.233.185.108 | E9: 100 | F9: 101 | G9: 1 | H9: 46200.254 | I9: R_5SvqgRsbh8VQ2MV | J9: 40.207 | K9: -75.0744 | L9: anonymous | M9: EN | N9: 1 | O9: 30 | P9: 1 | Q9: 43 | R9: 43 | S9: 43 | T9: 2 | U9: 43 | V9: 43 | W9: 43 | X9: 43 | Y9: 5 | Z9: 5 | AA9: 5 | AB9: 5 | AC9: 5 | AD9: 3 | AE9: 10 | AF9: 1 | AG9: 2 | AH9: 2 | AI9: It has all the sports games I want to watch
A10: 46200.256 | B10: 46200.257 | C10: 0 | D10: 107.127.13.55 | E10: 100 | F10: 82 | G10: 1 | H10: 46200.257 | I10: R_3ZUNk2hyCuw5ZBf | J10: 39.6635 | K10: -84.2439 | L10: anonymous | M10: EN | N10: 1 | O10: 1 | P10: 2 | Q10: 30 | R10: 43 | S10: 43 | T10: 43 | U10: 43 | V10: 43 | W10: 43 | X10: 43 | Y10: 1 | Z10: 1 | AA10: 3 | AB10: 4 | AC10: 3 | AD10: 1 | AE10: 3 | AF10: 1 | AG10: 5 | AH10: 1 | AI10: Variety of content
A11: 46200.258 | B11: 46200.259 | C11: 0 | D11: 73.230.83.35 | E11: 100 | F11: 80 | G11: 1 | H11: 46200.259 | I11: R_7tyPefbIqpeZzUt | J11: 40.3102 | K11: -76.0388 | L11: anonymous | M11: EN | N11: 1 | O11: 1 | P11: 43 | Q11: 43 | R11: 43 | S11: 43 | T11: 30 | U11: 43 | V11: 43 | W11: 2 | X11: 43 | Y11: 4 | Z11: 4 | AA11: 4 | AB11: 4 | AC11: 4 | AD11: 3 | AE11: 10 | AF11: 2 | AG11: 1 | AH11: 2
A12: 46200.261 | B12: 46200.262 | C12: 0 | D12: 107.222.119.137 | E12: 100 | F12: 122 | G12: 1 | H12: 46200.262 | I12: R_54ejdoXRz9glW4V | J12: 37.7548 | K12: -84.2985 | L12: anonymous | M12: EN | N12: 1 | O12: 1 | P12: 43 | Q12: 43 | R12: 2 | S12: 30 | T12: 43 | U12: 43 | V12: 43 | W12: 43 | X12: 43 | Y12: 5 | Z12: 5 | AA12: 5 | AB12: 4 | AC12: 3 | AD12: 2 | AE12: 8 | AF12: 2 | AG12: 4 | AH12: 1
A13: 46200.263 | B13: 46200.265 | C13: 0 | D13: 46.110.82.38 | E13: 100 | F13: 170 | G13: 1 | H13: 46200.265 | I13: R_3RAxeVk1gybD4UV | J13: 41.5749 | K13: -90.6087 | L13: anonymous | M13: EN | N13: 1 | O13: 1 | P13: 43 | Q13: 2 | R13: 43 | S13: 30 | T13: 43 | U13: 43 | V13: 43 | W13: 43 | X13: 43 | Y13: 5 | Z13: 5 | AA13: 5 | AB13: 4 | AC13: 4 | AD13: 2 | AE13: 8 | AF13: 1 | AG13: 2 | AH13: 2
A14: 46200.263 | B14: 46200.267 | C14: 0 | D14: 71.92.166.245 | E14: 100 | F14: 351 | G14: 1 | H14: 46200.267 | I14: R_741Vhs9459RUFHm | J14: 39.6261 | K14: -119.6996 | L14: anonymous | M14: EN | N14: 1 | O14: 30 | P14: 43 | Q14: 43 | R14: 43 | S14: 1 | T14: 43 | U14: 2 | V14: 43 | W14: 43 | X14: 43 | Y14: 5 | Z14: 5 | AA14: 5 | AB14: 2 | AC14: 3 | AD14: 2 | AE14: 8 | AF14: 2 | AG14: 4 | AH14: 1 | AI14: It has the best variety for my interests, and secondly it is seamlessly integrated to my Amazon usage making it feel like a package deal, finally it feels like a good value for what comes for free and I appreciate that items for purchase are available and reasonable.
A15: 46200.266 | B15: 46200.267 | C15: 0 | D15: 76.150.200.50 | E15: 100 | F15: 152 | G15: 1 | H15: 46200.267 | I15: R_72ZSk6QvARSSrvj | J15: 42.2739 | K15: -89.0474 | L15: anonymous | M15: EN | N15: 2 | O15: 30 | P15: 1 | Q15: 2 | R15: 43 | S15: 30 | T15: 43 | U15: 43 | V15: 43 | W15: 43 | X15: 43 | Y15: 4 | Z15: 4 | AA15: 3 | AB15: 3 | AC15: 3 | AD15: 2 | AE15: 7 | AF15: 1 | AG15: 3 | AH15: 1
A16: 46200.268 | B16: 46200.269 | C16: 0 | D16: 98.115.250.207 | E16: 100 | F16: 102 | G16: 1 | H16: 46200.269 | I16: R_5q3TSQI6QGhhCzT | J16: 40.2163 | K16: -74.7724 | L16: anonymous | M16: EN | N16: 1 | O16: 1 | P16: 43 | Q16: 2 | R16: 30 | S16: 43 | T16: 43 | U16: 43 | V16: 43 | W16: 43 | X16: 43 | Y16: 5 | Z16: 5 | AA16: 5 | AB16: 4 | AC16: 4 | AD16: 3 | AE16: 10 | AF16: 2 | AG16: 2 | AH16: 2 | AI16: I have kids who enjoy most of the content
A17: 46200.277 | B17: 46200.28 | C17: 0 | D17: 68.95.99.9 | E17: 100 | F17: 212 | G17: 1 | H17: 46200.28 | I17: R_674sTQixyebtHsl | J17: 35.2426 | K17: -80.741 | L17: anonymous | M17: EN | N17: 1 | O17: 1 | P17: 43 | Q17: 43 | R17: 43 | S17: 30 | T17: 43 | U17: 43 | V17: 2 | W17: 43 | X17: 43 | Y17: 5 | Z17: 5 | AA17: 5 | AB17: 5 | AC17: 5 | AD17: 3 | AE17: 10 | AF17: 2 | AG17: 1 | AH17: 1 | AI17: Frequency in new material and renewed series
A18: 46200.297 | B18: 46200.298 | C18: 0 | D18: 166.198.251.117 | E18: 100 | F18: 117 | G18: 1 | H18: 46200.298 | I18: R_7I6sxMMUhTZTXd0 | J18: 39.9587 | K18: -82.9987 | L18: anonymous | M18: EN | N18: 1 | O18: 1 | P18: 30 | Q18: 2 | R18: 43 | S18: 43 | T18: 43 | U18: 43 | V18: 43 | W18: 43 | X18: 43 | Y18: 4 | Z18: 4 | AA18: 4 | AB18: 3 | AC18: 4 | AD18: 2 | AE18: 7 | AF18: 1 | AG18: 2 | AH18: 1
A19: 46200.303 | B19: 46200.304 | C19: 0 | D19: 174.228.98.187 | E19: 100 | F19: 98 | G19: 1 | H19: 46200.304 | I19: R_6M4Bm4UdqQZ7cGe | J19: 41.8502 | K19: -87.6736 | L19: anonymous | M19: EN | N19: 1 | O19: 2 | P19: 30 | Q19: 43 | R19: 43 | S19: 43 | T19: 43 | U19: 43 | V19: 43 | W19: 1 | X19: 43 | Y19: 5 | Z19: 4 | AA19: 4 | AB19: 2 | AC19: 4 | AD19: 3 | AE19: 9 | AF19: 1 | AG19: 4 | AH19: 1 | AI19: Cost
A20: 46200.316 | B20: 46200.318 | C20: 0 | D20: 69.129.201.139 | E20: 100 | F20: 133 | G20: 1 | H20: 46200.318 | I20: R_6WBwbe6eGhcNDO9 | J20: 42.9958 | K20: -89.5499 | L20: anonymous | M20: EN | N20: 1 | O20: 43 | P20: 43 | Q20: 43 | R20: 1 | S20: 43 | T20: 30 | U20: 43 | V20: 2 | W20: 43 | X20: 43 | Y20: 5 | Z20: 4 | AA20: 3 | AB20: 4 | AC20: 2 | AD20: 1 | AE20: 6 | AF20: 2 | AG20: 5 | AH20: 1 | AI20: Options and movies
A21: 46200.321 | B21: 46200.324 | C21: 0 | D21: 45.50.19.40 | E21: 100 | F21: 243 | G21: 1 | H21: 46200.324 | I21: R_63UXNUwfBX2rEzr | J21: 33.93 | K21: -117.9477 | L21: anonymous | M21: EN | N21: 1 | O21: 2 | S21: 1 | T21: 43 | U21: 30 | V21: 43 | Y21: 5 | Z21: 4 | AA21: 4 | AB21: 4 | AC21: 3 | AD21: 3 | AE21: 9 | AF21: 2 | AG21: 2 | AH21: 2 | AI21: Wide variety of great programs, movies
A22: 46200.329 | B22: 46200.331 | C22: 0 | D22: 98.187.137.233 | E22: 100 | F22: 139 | G22: 1 | H22: 46200.331 | I22: R_31cSuUcibJ2P67v | J22: 36.1805 | K22: -94.5304 | L22: anonymous | M22: EN | N22: 1 | O22: 30 | P22: 43 | Q22: 1 | R22: 43 | S22: 43 | T22: 2 | U22: 43 | V22: 43 | W22: 43 | X22: 43 | Y22: 5 | Z22: 5 | AA22: 5 | AB22: 3 | AC22: 5 | AD22: 3 | AE22: 10 | AF22: 1 | AG22: 5 | AH22: 1 | AI22: It has content that I love. It isn't glitchy
A23: 46200.352 | B23: 46200.355 | C23: 0 | D23: 174.218.82.218 | E23: 100 | F23: 235 | G23: 1 | H23: 46200.355 | I23: R_6qId9hle9eQrLEZ | J23: 34.0587 | K23: -118.2781 | L23: anonymous | M23: EN | N23: 1 | O23: 30 | P23: 43 | Q23: 43 | R23: 43 | S23: 2 | T23: 43 | U23: 43 | V23: 43 | W23: 1 | X23: 43 | Y23: 5 | Z23: 5 | AA23: 5 | AB23: 5 | AC23: 5 | AD23: 3 | AE23: 10 | AF23: 1 | AG23: 2 | AH23: 2
A24: 46200.357 | B24: 46200.359 | C24: 0 | D24: 166.194.188.73 | E24: 100 | F24: 146 | G24: 1 | H24: 46200.359 | I24: R_7S2dmfcImtPm61L | J24: 40.1586 | K24: -75.282 | L24: anonymous | M24: EN | N24: 1 | O24: 1 | P24: 30 | Q24: 43 | R24: 43 | S24: 2 | T24: 43 | U24: 43 | V24: 43 | W24: 43 | X24: 43 | Y24: 5 | Z24: 4 | AA24: 4 | AB24: 3 | AC24: 3 | AD24: 2 | AE24: 8 | AF24: 2 | AG24: 4 | AH24: 1 | AI24: Ease of use
A25: 46200.382 | B25: 46200.384 | C25: 0 | D25: 96.8.181.44 | E25: 100 | F25: 112 | G25: 1 | H25: 46200.384 | I25: R_56mwUxLsllClm0k | J25: 29.7026 | K25: -98.4759 | L25: anonymous | M25: EN | N25: 1 | O25: 1 | P25: 2 | Q25: 30 | R25: 43 | S25: 43 | V25: 43 | Y25: 5 | Z25: 4 | AA25: 4 | AB25: 2 | AC25: 3 | AD25: 2 | AE25: 7 | AF25: 1 | AG25: 1 | AH25: 2 | AI25: New shows and movies
A26: 46200.419 | B26: 46200.421 | C26: 0 | D26: 166.194.143.48 | E26: 100 | F26: 95 | G26: 1 | H26: 46200.421 | I26: R_3Vm4Mn3XmtQFOBW | J26: 33.4683 | K26: -112.0549 | L26: anonymous | M26: EN | N26: 1 | O26: 1 | P26: 2 | Q26: 43 | R26: 43 | S26: 30 | T26: 43 | U26: 43 | V26: 43 | W26: 43 | X26: 43 | Y26: 5 | Z26: 4 | AA26: 4 | AB26: 3 | AC26: 3 | AD26: 2 | AE26: 7 | AF26: 1 | AG26: 3 | AH26: 1
A27: 46200.454 | B27: 46200.457 | C27: 0 | D27: 174.233.182.53 | E27: 100 | F27: 193 | G27: 1 | H27: 46200.457 | I27: R_3hxT0Fa09x9ob3E | J27: 41.923 | K27: -87.7531 | L27: anonymous | M27: EN | N27: 3 | O27: 43 | P27: 43 | Q27: 43 | R27: 43 | S27: 2 | T27: 1 | U27: 30 | V27: 43 | W27: 43 | X27: 43 | Y27: 4 | Z27: 4 | AA27: 4 | AB27: 2 | AC27: 4 | AD27: 2 | AE27: 7 | AF27: 2 | AG27: 2 | AH27: 2
A28: 46200.459 | B28: 46200.46 | C28: 0 | D28: 199.33.97.219 | E28: 100 | F28: 122 | G28: 1 | H28: 46200.46 | I28: R_62VmvvQJeNs4z42 | J28: 36.0154 | K28: -83.4149 | L28: anonymous | M28: EN | N28: 1 | O28: 1 | P28: 2 | Q28: 30 | R28: 43 | S28: 43 | T28: 43 | U28: 43 | V28: 43 | W28: 43 | X28: 43 | Y28: 5 | Z28: 5 | AA28: 5 | AB28: 3 | AC28: 4 | AD28: 2 | AE28: 7 | AF28: 1 | AG28: 3 | AH28: 1 | AI28: Most options that I enjoy
A29: 46200.507 | B29: 46200.512 | C29: 0 | D29: 45.50.19.40 | E29: 100 | F29: 393 | G29: 1 | H29: 46200.512 | I29: R_1QfFOKZrH3G9PKo | J29: 33.93 | K29: -117.9477 | L29: anonymous | M29: EN | N29: 2 | O29: 30 | P29: 43 | Q29: 43 | R29: 43 | S29: 1 | T29: 43 | U29: 2 | V29: 43 | W29: 43 | X29: 43 | Y29: 1 | Z29: 1 | AA29: 1 | AB29: 1 | AC29: 1 | AD29: 3 | AE29: 10 | AF29: 1 | AG29: 3 | AH29: 2
A30: 46200.51 | B30: 46200.512 | C30: 0 | D30: 172.56.221.80 | E30: 100 | F30: 192 | G30: 1 | H30: 46200.512 | I30: R_6Qrk0Vn5jyvsyZb | J30: 40.0598 | K30: -75.1448 | L30: anonymous | M30: EN | N30: 1 | O30: 43 | P30: 43 | Q30: 43 | R30: 1 | S30: 2 | T30: 43 | U30: 1 | V30: 43 | W30: 43 | X30: 43 | Y30: 5 | Z30: 5 | AA30: 5 | AB30: 3 | AC30: 5 | AD30: 3 | AE30: 10 | AF30: 1 | AG30: 3 | AH30: 2
A31: 46200.517 | B31: 46200.518 | C31: 0 | D31: 46.110.178.68 | E31: 100 | F31: 124 | G31: 1 | H31: 46200.518 | I31: R_5eeqaPh4tM7RVBA | J31: 41.4943 | K31: -90.5001 | L31: anonymous | M31: EN | N31: 1 | O31: 1 | P31: 43 | Q31: 43 | R31: 30 | S31: 43 | T31: 43 | U31: 43 | V31: 2 | W31: 43 | X31: 43 | Y31: 4 | Z31: 4 | AA31: 4 | AB31: 3 | AC31: 3 | AD31: 2 | AE31: 7 | AF31: 2 | AG31: 4 | AH31: 2 | AI31: Variety of options that rotate and no ads
A32: 46200.531 | B32: 46200.533 | C32: 0 | D32: 96.235.170.163 | E32: 100 | F32: 112 | G32: 1 | H32: 46200.533 | I32: R_1kjrMugsCpQsw1j | J32: 40.2381 | K32: -74.7822 | L32: anonymous | M32: EN | N32: 1 | O32: 30 | P32: 43 | Q32: 2 | R32: 43 | S32: 1 | T32: 43 | U32: 43 | V32: 43 | W32: 43 | X32: 43 | Y32: 5 | Z32: 4 | AA32: 3 | AB32: 3 | AC32: 3 | AD32: 1 | AE32: 5 | AF32: 3 | AG32: 4 | AH32: 1
A33: 46200.545 | B33: 46200.547 | C33: 0 | D33: 174.65.124.151 | E33: 100 | F33: 200 | G33: 1 | H33: 46200.547 | I33: R_1nJhS6UMRhoehhW | J33: 33.1097 | K33: -117.067 | L33: anonymous | M33: EN | N33: 1 | O33: 43 | P33: 1 | Q33: 43 | R33: 30 | S33: 43 | T33: 2 | U33: 2 | V33: 43 | W33: 43 | X33: 43 | Y33: 4 | Z33: 3 | AA33: 3 | AB33: 2 | AC33: 2 | AD33: 1 | AE33: 3 | AF33: 3 | AG33: 5 | AH33: 1 | AI33: The show I like is on it
A34: 46200.546 | B34: 46200.55 | C34: 0 | D34: 68.252.20.239 | E34: 100 | F34: 394 | G34: 1 | H34: 46200.551 | I34: R_1NVEsiRhTQYOGq1 | J34: 26.4141 | K34: -80.0972 | L34: anonymous | M34: EN | N34: 1 | O34: 2 | P34: 43 | Q34: 43 | R34: 1 | S34: 43 | T34: 43 | U34: 43 | V34: 30 | W34: 43 | X34: 43 | Y34: 5 | Z34: 5 | AA34: 5 | AB34: 5 | AC34: 5 | AD34: 3 | AE34: 10 | AF34: 2 | AG34: 1 | AH34: 2
A35: 46200.551 | B35: 46200.551 | C35: 0 | D35: 125.103.25.178 | E35: 100 | F35: 69 | G35: 1 | H35: 46200.551 | I35: R_4ikSj029XCm4KgV | J35: 35.6017 | K35: 139.7431 | L35: anonymous | M35: EN | N35: 1 | O35: 1 | P35: 2 | Q35: 43 | R35: 43 | S35: 30 | T35: 43 | U35: 43 | V35: 43 | W35: 43 | X35: 43 | Y35: 1 | Z35: 1 | AA35: 1 | AB35: 3 | AC35: 3 | AD35: 3 | AE35: 10 | AF35: 1 | AG35: 4 | AH35: 1
A36: 46200.552 | B36: 46200.554 | C36: 0 | D36: 68.252.20.239 | E36: 100 | F36: 183 | G36: 1 | H36: 46200.554 | I36: R_5rw7fSu7o833noW | J36: 26.4141 | K36: -80.0972 | L36: anonymous | M36: EN | N36: 1 | O36: 1 | P36: 30 | Q36: 30 | R36: 2 | S36: 43 | T36: 30 | U36: 30 | V36: 2 | W36: 43 | X36: 43 | Y36: 3 | Z36: 3 | AA36: 3 | AB36: 3 | AC36: 3 | AD36: 1 | AE36: 6 | AF36: 1 | AG36: 3 | AH36: 2 | AI36: Good movies
A37: 46200.602 | B37: 46200.604 | C37: 0 | D37: 70.95.14.154 | E37: 100 | F37: 125 | G37: 1 | H37: 46200.604 | I37: R_6mVqrmvvNS4opfb | J37: 32.9164 | K37: -117.1393 | L37: anonymous | M37: EN | N37: 2 | O37: 1 | P37: 43 | Q37: 43 | R37: 30 | S37: 43 | T37: 2 | U37: 43 | V37: 43 | W37: 43 | X37: 43 | Y37: 5 | Z37: 5 | AA37: 5 | AB37: 5 | AC37: 5 | AD37: 3 | AE37: 10 | AF37: 1 | AG37: 2 | AH37: 2
A38: 46200.569 | B38: 46200.664 | C38: 0 | D38: 73.165.241.59 | E38: 100 | F38: 8183 | G38: 1 | H38: 46200.664 | I38: R_7Su948qzfQifJnT | J38: 40.0146 | K38: -75.7136 | L38: anonymous | M38: EN | N38: 1 | O38: 43 | P38: 30 | Q38: 43 | R38: 43 | S38: 2 | T38: 43 | U38: 43 | V38: 43 | W38: 1 | X38: 43 | Y38: 3 | Z38: 3 | AA38: 4 | AB38: 3 | AC38: 3 | AD38: 1 | AE38: 6 | AF38: 1 | AG38: 2 | AH38: 2 | AI38: Affordability
A39: 46200.707 | B39: 46200.708 | C39: 0 | D39: 71.188.87.72 | E39: 100 | F39: 146 | G39: 1 | H39: 46200.708 | I39: R_5soXWh4QWeArnpx | J39: 40.3344 | K39: -74.795 | L39: anonymous | M39: EN | N39: 1 | O39: 43 | P39: 1 | Q39: 43 | R39: 2 | S39: 30 | T39: 43 | U39: 43 | V39: 43 | W39: 43 | X39: 43 | Y39: 5 | Z39: 1 | AA39: 5 | AB39: 5 | AC39: 5 | AD39: 3 | AE39: 10 | AF39: 1 | AG39: 1 | AH39: 2

Sheet Raw Qualtrics Data
A1: StartDate | B1: EndDate | C1: Status | D1: IPAddress | E1: Progress | F1: Duration (in seconds) | G1: Finished | H1: RecordedDate | I1: ResponseId | J1: RecipientLastName | K1: RecipientFirstName | L1: RecipientEmail | M1: ExternalReference | N1: LocationLatitude | O1: LocationLongitude | P1: DistributionChannel | Q1: UserLanguage | R1: Q1 | S1: Q2_1 | T1: Q2_2 | U1: Q2_3 | V1: Q2_4 | W1: Q2_5 | X1: Q2_6 | Y1: Q2_7 | Z1: Q2_8 | AA1: Q2_9 | AB1: Q2_10 | AC1: Q3_1 | AD1: Q3_2 | AE1: Q3_3 | AF1: Q3_4 | AG1: Q3_5 | AH1: Q4_NPS_GROUP | AI1: Q4 | AJ1: Q5 | AK1: Q6 | AL1: Q7 | AM1: Q8
A2: Start Date | B2: End Date | C2: Response Type | D2: IP Address | E2: Progress | F2: Duration (in seconds) | G2: Finished | H2: Recorded Date | I2: Response ID | J2: Recipient Last Name | K2: Recipient First Name | L2: Recipient Email | M2: External Data Reference | N2: Location Latitude | O2: Location Longitude | P2: Distribution Channel | Q2: User Language | R2: Which statement best describes your role in streaming service decisions for your household? | S2: Please rank each streaming service based on how often you use it. Select First Most Used Service for the streaming service you use the most. Select Second Most Used Service for the service you use second most. Select Third Most Used Service for the service you use third most. For all other services, select Other (Not in top 3). - Netflix | T2: Please rank each streaming service based on how often you use it. Select First Most Used Service for the streaming service you use the most. Select Second Most Used Service for the service you use second most. Select Third Most Used Service for the service you use third most. For all other services, select Other (Not in top 3). - Hulu | U2: Please rank each streaming service based on how often you use it. Select First Most Used Service for the streaming service you use the most. Select Second Most Used Service for the service you use second most. Select Third Most Used Service for the service you use third most. For all other services, select Other (Not in top 3). - Disney+ | V2: Please rank each streaming service based on how often you use it. Select First Most Used Service for the streaming service you use the most. Select Second Most Used Service for the service you use second most. Select Third Most Used Service for the service you use third most. For all other services, select Other (Not in top 3). - Max | W2: Please rank each streaming service based on how often you use it. Select First Most Used Service for the streaming service you use the most. Select Second Most Used Service for the service you use second most. Select Third Most Used Service for the service you use third most. For all other services, select Other (Not in top 3). - Prime Video | X2: Please rank each streaming service based on how often you use it. Select First Most Used Service for the streaming service you use the most. Select Second Most Used Service for the service you use second most. Select Third Most Used Service for the service you use third most. For all other services, select Other (Not in top 3). - Peacock | Y2: Please rank each streaming service based on how often you use it. Select First Most Used Service for the streaming service you use the most. Select Second Most Used Service for the service you use second most. Select Third Most Used Service for the service you use third most. For all other services, select Other (Not in top 3). - Paramount+ | Z2: Please rank each streaming service based on how often you use it. Select First Most Used Service for the streaming service you use the most. Select Second Most Used Service for the service you use second most. Select Third Most Used Service for the service you use third most. For all other services, select Other (Not in top 3). - Apple TV+ | AA2: Please rank each streaming service based on how often you use it. Select First Most Used Service for the streaming service you use the most. Select Second Most Used Service for the service you use second most. Select Third Most Used Service for the service you use third most. For all other services, select Other (Not in top 3). - YouTube TV | AB2: Please rank each streaming service based on how often you use it. Select First Most Used Service for the streaming service you use the most. Select Second Most Used Service for the service you use second most. Select Third Most Used Service for the service you use third most. For all other services, select Other (Not in top 3). - Other | AC2: Please indicate your level of agreement with the following statements about the streaming service you use most often. - I intend to keep using this streaming service. | AD2: Please indicate your level of agreement with the following statements about the streaming service you use most often. - This streaming service would be one of my first choices. | AE2: Please indicate your level of agreement with the following statements about the streaming service you use most often. - I would recommend this streaming service to others. | AF2: Please indicate your level of agreement with the following statements about the streaming service you use most often. - I would not easily switch to a competing streaming service. | AG2: Please indicate your level of agreement with the following statements about the streaming service you use most often. - I trust this streaming service. | AH2: How likely are you to recommend the streaming service you use most often to a friend or colleague? - Group | AI2: How likely are you to recommend the streaming service you use most often to a friend or colleague? | AJ2: In the past 6 months, how often have you used the streaming service you ranked as #1? | AK2: How likely are you to cancel at least one streaming service in the next 6 months? | AL2: Have you canceled a streaming service within the past year? | AM2: What is the main reason you would continue using the streaming service you ranked as your first most used service? (Optional)
